Microsoft Windows [Version 10.0.18363.1556]
(c) Корпорация Майкрософт (Microsoft Corporation), 2019. Все права защищены.

C:\Users\User>cd Desktop

C:\Users\User\Desktop>cd try_project

C:\Users\User\Desktop\try_project>dir
 Том в устройстве C имеет метку OS
 Серийный номер тома: F6DE-2117

 Содержимое папки C:\Users\User\Desktop\try_project

17.12.2023  01:56    <DIR>          .
17.12.2023  01:56    <DIR>          ..
17.12.2023  01:53                 0 .gitignore
16.12.2023  23:43    <DIR>          blog
16.12.2023  22:52           139 264 db.sqlite3
16.12.2023  21:32    <DIR>          env
16.12.2023  23:01    <DIR>          HelloDjango
16.12.2023  21:43               689 manage.py
17.12.2023  01:56                 0 README.md
16.12.2023  21:38                 0 requirements.txt
               5 файлов        139 953 байт
               5 папок   2 373 689 344 байт свободно

C:\Users\User\Desktop\try_project>cd env

C:\Users\User\Desktop\try_project\env>cd..

C:\Users\User\Desktop\try_project>env\Scripts\activate

(env) C:\Users\User\Desktop\try_project>python manage.py shell
Python 3.8.3 (tags/v3.8.3:6f8c832, May 13 2020, 22:20:19) [MSC v.1925 32 bit (Intel)] on win32
Type "help", "copyright", "credits" or "license" for more information.
(InteractiveConsole)
>>> from blog.models import Post
>>> Post.objects.all()
<QuerySet []>
>>> Post.oblects.create(title="Заголовок", text="Текст статьи")
Traceback (most recent call last):
  File "<console>", line 1, in <module>
AttributeError: type object 'Post' has no attribute 'oblects'
>>> Post.objects.create(title="Заголовок", text="Текст статьи")
Traceback (most recent call last):
  File "C:\Users\User\Desktop\try_project\env\lib\site-packages\django\db\backends\utils.py", line 89, in _execute
    return self.cursor.execute(sql, params)
  File "C:\Users\User\Desktop\try_project\env\lib\site-packages\django\db\backends\sqlite3\base.py", line 328, in execute
    return super().execute(query, params)
sqlite3.IntegrityError: NOT NULL constraint failed: blog_post.author_id

The above exception was the direct cause of the following exception:

Traceback (most recent call last):
  File "<console>", line 1, in <module>
  File "C:\Users\User\Desktop\try_project\env\lib\site-packages\django\db\models\manager.py", line 87, in manager_method
    return getattr(self.get_queryset(), name)(*args, **kwargs)
  File "C:\Users\User\Desktop\try_project\env\lib\site-packages\django\db\models\query.py", line 658, in create
    obj.save(force_insert=True, using=self.db)
  File "C:\Users\User\Desktop\try_project\env\lib\site-packages\django\db\models\base.py", line 814, in save
    self.save_base(
  File "C:\Users\User\Desktop\try_project\env\lib\site-packages\django\db\models\base.py", line 877, in save_base
    updated = self._save_table(
  File "C:\Users\User\Desktop\try_project\env\lib\site-packages\django\db\models\base.py", line 1020, in _save_table
    results = self._do_insert(
  File "C:\Users\User\Desktop\try_project\env\lib\site-packages\django\db\models\base.py", line 1061, in _do_insert
    return manager._insert(
  File "C:\Users\User\Desktop\try_project\env\lib\site-packages\django\db\models\manager.py", line 87, in manager_method
    return getattr(self.get_queryset(), name)(*args, **kwargs)
  File "C:\Users\User\Desktop\try_project\env\lib\site-packages\django\db\models\query.py", line 1805, in _insert
    return query.get_compiler(using=using).execute_sql(returning_fields)
  File "C:\Users\User\Desktop\try_project\env\lib\site-packages\django\db\models\sql\compiler.py", line 1822, in execute_sql
    cursor.execute(sql, params)
  File "C:\Users\User\Desktop\try_project\env\lib\site-packages\django\db\backends\utils.py", line 102, in execute
    return super().execute(sql, params)
  File "C:\Users\User\Desktop\try_project\env\lib\site-packages\django\db\backends\utils.py", line 67, in execute
    return self._execute_with_wrappers(
  File "C:\Users\User\Desktop\try_project\env\lib\site-packages\django\db\backends\utils.py", line 80, in _execute_with_wrappers
    return executor(sql, params, many, context)
  File "C:\Users\User\Desktop\try_project\env\lib\site-packages\django\db\backends\utils.py", line 89, in _execute
    return self.cursor.execute(sql, params)
  File "C:\Users\User\Desktop\try_project\env\lib\site-packages\django\db\utils.py", line 91, in __exit__
    raise dj_exc_value.with_traceback(traceback) from exc_value
  File "C:\Users\User\Desktop\try_project\env\lib\site-packages\django\db\backends\utils.py", line 89, in _execute
    return self.cursor.execute(sql, params)
  File "C:\Users\User\Desktop\try_project\env\lib\site-packages\django\db\backends\sqlite3\base.py", line 328, in execute
    return super().execute(query, params)
django.db.utils.IntegrityError: NOT NULL constraint failed: blog_post.author_id
>>> from django.contrib.auth.models import user
Traceback (most recent call last):
  File "<console>", line 1, in <module>
ImportError: cannot import name 'user' from 'django.contrib.auth.models' (C:\Users\User\Desktop\try_project\env\lib\site-packages\django\contrib\auth\models.py)
>>> from django.contrib.auth.models import User
>>> User.objects.all()
<QuerySet [<User: ADMIN>]>
>>> me = User.objects.get(username="ADMIN")
>>> me
<User: ADMIN>
>>> Post.objects.create(author=me, title="Sample #1", text="Description")
<Post: Sample #1>
>>> Post.objects.all()
<QuerySet [<Post: Sample #1>]>
>>> Post.objects.create(author=me, title="Sample #2", text="Description"
...
...
...
...
KeyboardInterrupt
>>> Post.objects.all()
<QuerySet [<Post: Sample #1>]>
>>> from blog.models import Post
>>> post = Post.objects.filter(title__contains="Sample").first()
>>> post.publish()
>>> Post.objects.all()
<QuerySet [<Post: Sample #1>]>
>>>